Workbook

Sheet Start Here
B2: Commercial Landscaping Pricing Engine
B3: MVP v1 | NW Houston (Tomball / Spring / Cypress / Magnolia corridor)
B5: How this works
B6: 1. Open the INPUTS tab. Edit only the yellow cells. Those are your friend's real cost numbers and pricing rules.
B7: 2. Use PROPERTY CALCULATOR to price one property at a time. Type the measured areas in the yellow cells; price and review flags update automatically.
B8: 3. Use BATCH PIPELINE to paste 15-20 properties at once. Each row prices itself and flags anything that needs your eyes before it goes out.
B9: 4. MARKET REFERENCE shows the Texas benchmark numbers behind the defaults, with sources, so you can sanity-check or update them.
B11: The golden rule
B12: Blue/yellow = you change it. Black = the model calculates it, leave it alone.
B14: What 'Needs Review = YES' means
B15: The property tripped a guardrail (too big, bed-heavy, high dollar value, low measurement confidence, or priced outside the market band).
B16: A human should eyeball it before the proposal is sent. This protects the margin, which is also your profit split.
... B25: Finalize later whether the split is on gross profit or net of shared overhead. The cell is a placeholder at 50%.

Sheet INPUTS
B2: INPUTS — edit only the yellow cells
B4: CREW & COST BASIS
B5: Crew size (people) | C5: 3 | E5: Typical small commercial crew running together.
B6: Loaded labor cost ($ / person-hour) | C6: 22 | E6: TX laborer wage ~$15-18/hr base, loaded ~1.4x for payroll tax, workers comp, GL insurance.
B7: Equipment + truck cost ($ / crew-hour) | C7: 30 | E7: Fuel, maintenance, depreciation on mowers/trailer/truck.
B8: Crew cost ($ / hour) [calc] | C8: =C5*C6+C7 -> 96 | E8: Auto: (crew size x labor) + equipment.
B10: PRODUCTION RATES (crew wall-clock minutes)
B11: Turf mow/edge/trim/blow (min per acre) | C11: 38 | E11: Calibrated to commercial crew efficiency. Raise if turf is obstacle-heavy.
B12: Bed light maintenance (min per 1,000 sqft) | C12: 4 | E12: Weekly light weed/check. Deep mulch/bed work is a separate enhancement, not in base.
B13: Fixed time per stop - load/unload/blow (min) | C13: 10 | E13: Per-visit overhead regardless of size.
B14: Avg drive time between stops (min) | C14: 10 | E14: Route density lever. Denser route = lower = better margin. Suburban advantage.
B15: Default site complexity factor (x) | C15: 1 | E15: 1.0 simple/open. 1.2-1.4 for islands, tight trimming, obstacles.
B17: PRICING & MARGIN
B18: Target gross margin (%) | C18: 0.4 | E18: Drives the quoted price.
B19: Minimum gross margin floor (%) | C19: 0.35 | E19: Below this on any deal = review. Lowest you should accept.
B20: Minimum price per visit ($) | C20: 70 | E20: Floor for tiny lots. Most commercial stops bill a minimum.
B21: Visits per year | C21: 40 | E21: Houston: ~30 weekly in-season + ~10 biweekly shoulder. Billed as 12 equal months.
B23: PROFIT SPLIT (your incentive)
B24: Cole's profit share (%) | C24: 0.5 | E24: Applied to annual GROSS profit per account. Placeholder; finalize structure later.
B26: REVIEW GUARDRAILS (trigger human eyes)
B27: Max turf acres before review | C27: 3 | E27: Big properties = bigger risk if mismeasured.
B28: Bed-to-turf ratio review threshold (%) | C28: 0.2 | E28: Bed-heavy sites are labor-heavy; base mow rate may underprice.
B29: Monthly price review threshold ($) | C29: 1500 | E29: High-dollar deals get a human look.
B30: Market floor ($/acre/visit) | C30: 50 | E30: Below this (1+ acre lots) = likely underpriced / bad inputs.
B31: Market ceiling ($/acre/visit) | C31: 150 | E31: Above this (1+ acre lots) = may lose the bid.

Sheet PROPERTY CALCULATOR
B2: PROPERTY CALCULATOR — price one property
B4: PROPERTY MEASUREMENTS (from SiteRecon takeoff)
B5: Property name | C5: Example: 249 Self-Storage
B6: Address | C6: Tomball, TX
B7: Turf area (sqft) | C7: 35000 | E7: From takeoff.
B8: Bed area (sqft) | C8: 1500 | E8: Mulch / planting beds.
B9: Shrub count | C9: 20 | E9: Informational for scope; trimming is a periodic add-on.
B10: Tree count | C10: 6 | E10: Informational.
B11: Edging (linear ft) | C11: 600 | E11: Informational; trim/edge already in turf rate.
B12: Site complexity factor (x) | C12: =INPUTS!C15 -> 1 | E12: Override per property. 1.0 simple, up to 1.4 complex.
B13: Measurement confidence | C13: High | E13: High / Med / Low. Low triggers review.
B16: LABOR & COST (per visit)
B17: Turf acres | C17: =C7/43560 -> 0.80348944
B18: Turf time (crew-min) | C18: =C17*INPUTS!$C$11*C12 -> 30.532599
B19: Bed time (crew-min) | C19: =(C8/1000)*INPUTS!$C$12*C12 -> 6
B20: Fixed per-stop (crew-min) | C20: =INPUTS!$C$13 -> 10
B21: Drive time (crew-min) | C21: =INPUTS!$C$14 -> 10
B22: Total crew-min / visit | C22: =SUM(C18:C21) -> 56.532599
B23: Crew-hours / visit | C23: =C22/60 -> 0.94220998
B24: Cost / visit ($) | C24: =C23*INPUTS!$C$8 -> 90.452158
B26: PRICE & MARGIN
B27: Price / visit ($) | C27: =MAX(C24/(1-INPUTS!$C$18),INPUTS!$C$20) -> 150.7536 | E27: Target margin, never below the per-visit minimum.
B28: Gross profit / visit ($) | C28: =C27-C24 -> 60.301439
B29: Gross margin (%) | C29: =IF(C27=0,0,C28/C27) -> 0.4
B30: Min acceptable price / visit ($) | C30: =MAX(C24/(1-INPUTS!$C$19),INPUTS!$C$20) -> 139.15717 | E30: Floor at the margin floor. Don't go below this.
B32: CONTRACT VALUE
B33: Monthly price (annualized, $) | C33: =C27*INPUTS!$C$21/12 -> 502.51199 | E33: Bill this each month, 12 equal payments.
B34: Annual price ($) | C34: =C27*INPUTS!$C$21 -> 6030.1439
B35: Annual gross profit ($) | C35: =C28*INPUTS!$C$21 -> 2412.0575
B36: Cole's annual cut ($) | C36: =C35*INPUTS!$C$24 -> 1206.0288 | E36: Your share of this account per year.
B38: MARKET SANITY CHECK
B39: Implied $ / acre / visit | C39: =IF(C17=0,"",C27/C17) -> 187.62362 | E39: Compare to $50-150/acre band (meaningful at 1+ acre).
B40: Implied $ / acre / month | C40: =IF(C17=0,"",C33/C17) -> 625.41206
B42: REVIEW FLAGS
B43: Large property | C43: =IF(C17>INPUTS!$C$27,"REVIEW: large property","OK") -> OK
B44: Bed-heavy | C44: =IF(C7=0,"REVIEW: no turf entered",IF((C8/C7)>INPUTS!$C$28,"REVIEW: bed-heavy vs turf","OK")) -> OK
B45: High-value | C45: =IF(C33>INPUTS!$C$29,"REVIEW: high-value deal","OK") -> OK
B46: Measurement confidence | C46: =IF(C13="Low","REVIEW: low measurement confidence","OK") -> OK
B47: Below market floor | C47: =IF(C17>=1,IF((C27/C17)<INPUTS!$C$30,"REVIEW: below market floor","OK"),"n/a (small lot)") -> n/a (small lot)
B48: Above market ceiling | C48: =IF(C17>=1,IF((C27/C17)>INPUTS!$C$31,"REVIEW: above market ceiling","OK"),"n/a (small lot)") -> n/a (small lot)
...

Sheet BATCH PIPELINE
A1: BATCH PIPELINE — paste your 15-20 MVP properties in the yellow columns (A-H). Everything else auto-calculates.
A3: Property | B3: Address | C3: Turf sqft | D3: Bed sqft | E3: Shrubs | F3: Trees | G3: Complexity | H3: Confidence | I3: Turf acres | J3: Crew-hrs/visit | K3: Cost/visit | L3: Price/visit | M3: Monthly | N3: Annual | O3: Margin % | P3: $/acre/visit | Q3: Cole annual cut | R3: Flags | S3: Needs review
A4: 249 Self-Storage | B4: SH-249, Tomball | C4: 35000 | D4: 1500 | E4: 20 | F4: 6 | G4: 1 | H4: High | I4: =IF($C4="","",$C4/43560) -> 0.80348944 | J4: =IF($C4="","",((I4*INPUTS!$C$11*$G4)+(($D4/1000)*INPUTS!$C$12*$G4)+INPUTS!$C$13+INPUTS!$C$14)/60) -> 0.94220998 | K4: =IF($C4="","",J4*INPUTS!$C$8) -> 90.452158 | L4: =IF($C4="","",MAX(K4/(1-INPUTS!$C$18),INPUTS!$C$20)) -> 150.7536 | M4: =IF($C4="","",L4*INPUTS!$C$21/12) -> 502.51199 | N4: =IF($C4="","",L4*INPUTS!$C$21) -> 6030.1439 | O4: =IF($C4="","",(L4-K4)/L4) -> 0.4 | P4: =IF(OR($C4="",I4=0),"",L4/I4) -> 187.62362 | Q4: =IF($C4="","",(L4-K4)*INPUTS!$C$21*INPUTS!$C$24) -> 1206.0288 | R4: =IF($C4="","",TRIM(IF(I4>INPUTS!$C$27,"Large; ","")&IF(AND($C4>0,($D4/$C4)>INPUTS!$C$28),"Bed-heavy; ","")&IF(M4>INPUTS!$C$29,"High-value; ","")&IF($H4="Low","Low-confidence; ","")&IF(AND(I4>=1,IFERROR(L4/I4,0)<INPUTS!$C$30),"Below-market; ","")&IF(AND(I4>=1,IFERROR(L4/I4,0)>INPUTS!$C$31),"Above-market; ",""))) | S4: =IF($C4="","",IF(R4="","NO","YES")) -> NO
A5: Tomball Office Park | B5: FM-2920, Tomball | C5: 18000 | D5: 4000 | E5: 45 | F5: 12 | G5: 1.2 | H5: High | I5: =IF($C5="","",$C5/43560) -> 0.41322314 | J5: =IF($C5="","",((I5*INPUTS!$C$11*$G5)+(($D5/1000)*INPUTS!$C$12*$G5)+INPUTS!$C$13+INPUTS!$C$14)/60) -> 0.96738292 | K5: =IF($C5="","",J5*INPUTS!$C$8) -> 92.86876 | L5: =IF($C5="","",MAX(K5/(1-INPUTS!$C$18),INPUTS!$C$20)) -> 154.78127 | M5: =IF($C5="","",L5*INPUTS!$C$21/12) -> 515.93756 | N5: =IF($C5="","",L5*INPUTS!$C$21) -> 6191.2507 | O5: =IF($C5="","",(L5-K5)/L5) -> 0.4 | P5: =IF(OR($C5="",I5=0),"",L5/I5) -> 374.57067 | Q5: =IF($C5="","",(L5-K5)*INPUTS!$C$21*INPUTS!$C$24) -> 1238.2501 | R5: =IF($C5="","",TRIM(IF(I5>INPUTS!$C$27,"Large; ","")&IF(AND($C5>0,($D5/$C5)>INPUTS!$C$28),"Bed-heavy; ","")&IF(M5>INPUTS!$C$29,"High-value; ","")&IF($H5="Low","Low-confidence; ","")&IF(AND(I5>=1,IFERROR(L5/I5,0)<INPUTS!$C$30),"Below-market; ","")&IF(AND(I5>=1,IFERROR(L5/I5,0)>INPUTS!$C$31),"Above-market; ",""))) -> Bed-heavy; | S5: =IF($C5="","",IF(R5="","NO","YES")) -> YES
A6: Magnolia Community Church | B6: FM-1488, Magnolia | C6: 90000 | D6: 2000 | E6: 15 | F6: 10 | G6: 1 | H6: Med | I6: =IF($C6="","",$C6/43560) -> 2.0661157 | J6: =IF($C6="","",((I6*INPUTS!$C$11*$G6)+(($D6/1000)*INPUTS!$C$12*$G6)+INPUTS!$C$13+INPUTS!$C$14)/60) -> 1.7752066 | K6: =IF($C6="","",J6*INPUTS!$C$8) -> 170.41983 | L6: =IF($C6="","",MAX(K6/(1-INPUTS!$C$18),INPUTS!$C$20)) -> 284.03306 | M6: =IF($C6="","",L6*INPUTS!$C$21/12) -> 946.77686 | N6: =IF($C6="","",L6*INPUTS!$C$21) -> 11361.322 | O6: =IF($C6="","",(L6-K6)/L6) -> 0.4 | P6: =IF(OR($C6="",I6=0),"",L6/I6) -> 137.472 | Q6: =IF($C6="","",(L6-K6)*INPUTS!$C$21*INPUTS!$C$24) -> 2272.2645 | R6: =IF($C6="","",TRIM(IF(I6>INPUTS!$C$27,"Large; ","")&IF(AND($C6>0,($D6/$C6)>INPUTS!$C$28),"Bed-heavy; ","")&IF(M6>INPUTS!$C$29,"High-value; ","")&IF($H6="Low","Low-confidence; ","")&IF(AND(I6>=1,IFERROR(L6/I6,0)<INPUTS!$C$30),"Below-market; ","")&IF(AND(I6>=1,IFERROR(L6/I6,0)>INPUTS!$C$31),"Above-market; ",""))) | S6: =IF($C6="","",IF(R6="","NO","YES")) -> NO
I7: =IF($C7="","",$C7/43560) | J7: =IF($C7="","",((I7*INPUTS!$C$11*$G7)+(($D7/1000)*INPUTS!$C$12*$G7)+INPUTS!$C$13+INPUTS!$C$14)/60) | K7: =IF($C7="","",J7*INPUTS!$C$8) | L7: =IF($C7="","",MAX(K7/(1-INPUTS!$C$18),INPUTS!$C$20)) | M7: =IF($C7="","",L7*INPUTS!$C$21/12) | N7: =IF($C7="","",L7*INPUTS!$C$21) | O7: =IF($C7="","",(L7-K7)/L7) | P7: =IF(OR($C7="",I7=0),"",L7/I7) | Q7: =IF($C7="","",(L7-K7)*INPUTS!$C$21*INPUTS!$C$24) | R7: =IF($C7="","",TRIM(IF(I7>INPUTS!$C$27,"Large; ","")&IF(AND($C7>0,($D7/$C7)>INPUTS!$C$28),"Bed-heavy; ","")&IF(M7>INPUTS!$C$29,"High-value; ","")&IF($H7="Low","Low-confidence; ","")&IF(AND(I7>=1,IFERROR(L7/I7,0)<INPUTS!$C$30),"Below-market; ","")&IF(AND(I7>=1,IFERROR(L7/I7,0)>INPUTS!$C$31),"Above-market; ",""))) | S7: =IF($C7="","",IF(R7="","NO","YES"))
I8: =IF($C8="","",$C8/43560) | J8: =IF($C8="","",((I8*INPUTS!$C$11*$G8)+(($D8/1000)*INPUTS!$C$12*$G8)+INPUTS!$C$13+INPUTS!$C$14)/60) | K8: =IF($C8="","",J8*INPUTS!$C$8) | L8: =IF($C8="","",MAX(K8/(1-INPUTS!$C$18),INPUTS!$C$20)) | M8: =IF($C8="","",L8*INPUTS!$C$21/12) | N8: =IF($C8="","",L8*INPUTS!$C$21) | O8: =IF($C8="","",(L8-K8)/L8) | P8: =IF(OR($C8="",I8=0),"",L8/I8) | Q8: =IF($C8="","",(L8-K8)*INPUTS!$C$21*INPUTS!$C$24) | R8: =IF($C8="","",TRIM(IF(I8>INPUTS!$C$27,"Large; ","")&IF(AND($C8>0,($D8/$C8)>INPUTS!$C$28),"Bed-heavy; ","")&IF(M8>INPUTS!$C$29,"High-value; ","")&IF($H8="Low","Low-confidence; ","")&IF(AND(I8>=1,IFERROR(L8/I8,0)<INPUTS!$C$30),"Below-market; ","")&IF(AND(I8>=1,IFERROR(L8/I8,0)>INPUTS!$C$31),"Above-market; ",""))) | S8: =IF($C8="","",IF(R8="","NO","YES"))
I9: =IF($C9="","",$C9/43560) | J9: =IF($C9="","",((I9*INPUTS!$C$11*$G9)+(($D9/1000)*INPUTS!$C$12*$G9)+INPUTS!$C$13+INPUTS!$C$14)/60) | K9: =IF($C9="","",J9*INPUTS!$C$8) | L9: =IF($C9="","",MAX(K9/(1-INPUTS!$C$18),INPUTS!$C$20)) | M9: =IF($C9="","",L9*INPUTS!$C$21/12) | N9: =IF($C9="","",L9*INPUTS!$C$21) | O9: =IF($C9="","",(L9-K9)/L9) | P9: =IF(OR($C9="",I9=0),"",L9/I9) | Q9: =IF($C9="","",(L9-K9)*INPUTS!$C$21*INPUTS!$C$24) | R9: =IF($C9="","",TRIM(IF(I9>INPUTS!$C$27,"Large; ","")&IF(AND($C9>0,($D9/$C9)>INPUTS!$C$28),"Bed-heavy; ","")&IF(M9>INPUTS!$C$29,"High-value; ","")&IF($H9="Low","Low-confidence; ","")&IF(AND(I9>=1,IFERROR(L9/I9,0)<INPUTS!$C$30),"Below-market; ","")&IF(AND(I9>=1,IFERROR(L9/I9,0)>INPUTS!$C$31),"Above-market; ",""))) | S9: =IF($C9="","",IF(R9="","NO","YES"))
I10: =IF($C10="","",$C10/43560) | J10: =IF($C10="","",((I10*INPUTS!$C$11*$G10)+(($D10/1000)*INPUTS!$C$12*$G10)+INPUTS!$C$13+INPUTS!$C$14)/60) | K10: =IF($C10="","",J10*INPUTS!$C$8) | L10: =IF($C10="","",MAX(K10/(1-INPUTS!$C$18),INPUTS!$C$20)) | M10: =IF($C10="","",L10*INPUTS!$C$21/12) | N10: =IF($C10="","",L10*INPUTS!$C$21) | O10: =IF($C10="","",(L10-K10)/L10) | P10: =IF(OR($C10="",I10=0),"",L10/I10) | Q10: =IF($C10="","",(L10-K10)*INPUTS!$C$21*INPUTS!$C$24) | R10: =IF($C10="","",TRIM(IF(I10>INPUTS!$C$27,"Large; ","")&IF(AND($C10>0,($D10/$C10)>INPUTS!$C$28),"Bed-heavy; ","")&IF(M10>INPUTS!$C$29,"High-value; ","")&IF($H10="Low","Low-confidence; ","")&IF(AND(I10>=1,IFERROR(L10/I10,0)<INPUTS!$C$30),"Below-market; ","")&IF(AND(I10>=1,IFERROR(L10/I10,0)>INPUTS!$C$31),"Above-market; ",""))) | S10: =IF($C10="","",IF(R10="","NO","YES"))
I11: =IF($C11="","",$C11/43560) | J11: =IF($C11="","",((I11*INPUTS!$C$11*$G11)+(($D11/1000)*INPUTS!$C$12*$G11)+INPUTS!$C$13+INPUTS!$C$14)/60) | K11: =IF($C11="","",J11*INPUTS!$C$8) | L11: =IF($C11="","",MAX(K11/(1-INPUTS!$C$18),INPUTS!$C$20)) | M11: =IF($C11="","",L11*INPUTS!$C$21/12) | N11: =IF($C11="","",L11*INPUTS!$C$21) | O11: =IF($C11="","",(L11-K11)/L11) | P11: =IF(OR($C11="",I11=0),"",L11/I11) | Q11: =IF($C11="","",(L11-K11)*INPUTS!$C$21*INPUTS!$C$24) | R11: =IF($C11="","",TRIM(IF(I11>INPUTS!$C$27,"Large; ","")&IF(AND($C11>0,($D11/$C11)>INPUTS!$C$28),"Bed-heavy; ","")&IF(M11>INPUTS!$C$29,"High-value; ","")&IF($H11="Low","Low-confidence; ","")&IF(AND(I11>=1,IFERROR(L11/I11,0)<INPUTS!$C$30),"Below-market; ","")&IF(AND(I11>=1,IFERROR(L11/I11,0)>INPUTS!$C$31),"Above-market; ",""))) | S11: =IF($C11="","",IF(R11="","NO","YES"))
I12: =IF($C12="","",$C12/43560) | J12: =IF($C12="","",((I12*INPUTS!$C$11*$G12)+(($D12/1000)*INPUTS!$C$12*$G12)+INPUTS!$C$13+INPUTS!$C$14)/60) | K12: =IF($C12="","",J12*INPUTS!$C$8) | L12: =IF($C12="","",MAX(K12/(1-INPUTS!$C$18),INPUTS!$C$20)) | M12: =IF($C12="","",L12*INPUTS!$C$21/12) | N12: =IF($C12="","",L12*INPUTS!$C$21) | O12: =IF($C12="","",(L12-K12)/L12) | P12: =IF(OR($C12="",I12=0),"",L12/I12) | Q12: =IF($C12="","",(L12-K12)*INPUTS!$C$21*INPUTS!$C$24) | R12: =IF($C12="","",TRIM(IF(I12>INPUTS!$C$27,"Large; ","")&IF(AND($C12>0,($D12/$C12)>INPUTS!$C$28),"Bed-heavy; ","")&IF(M12>INPUTS!$C$29,"High-value; ","")&IF($H12="Low","Low-confidence; ","")&IF(AND(I12>=1,IFERROR(L12/I12,0)<INPUTS!$C$30),"Below-market; ","")&IF(AND(I12>=1,IFERROR(L12/I12,0)>INPUTS!$C$31),"Above-market; ",""))) | S12: =IF($C12="","",IF(R12="","NO","YES"))
I13: =IF($C13="","",$C13/43560) | J13: =IF($C13="","",((I13*INPUTS!$C$11*$G13)+(($D13/1000)*INPUTS!$C$12*$G13)+INPUTS!$C$13+INPUTS!$C$14)/60) | K13: =IF($C13="","",J13*INPUTS!$C$8) | L13: =IF($C13="","",MAX(K13/(1-INPUTS!$C$18),INPUTS!$C$20)) | M13: =IF($C13="","",L13*INPUTS!$C$21/12) | N13: =IF($C13="","",L13*INPUTS!$C$21) | O13: =IF($C13="","",(L13-K13)/L13) | P13: =IF(OR($C13="",I13=0),"",L13/I13) | Q13: =IF($C13="","",(L13-K13)*INPUTS!$C$21*INPUTS!$C$24) | R13: =IF($C13="","",TRIM(IF(I13>INPUTS!$C$27,"Large; ","")&IF(AND($C13>0,($D13/$C13)>INPUTS!$C$28),"Bed-heavy; ","")&IF(M13>INPUTS!$C$29,"High-value; ","")&IF($H13="Low","Low-confidence; ","")&IF(AND(I13>=1,IFERROR(L13/I13,0)<INPUTS!$C$30),"Below-market; ","")&IF(AND(I13>=1,IFERROR(L13/I13,0)>INPUTS!$C$31),"Above-market; ",""))) | S13: =IF($C13="","",IF(R13="","NO","YES"))
I14: =IF($C14="","",$C14/43560) | J14: =IF($C14="","",((I14*INPUTS!$C$11*$G14)+(($D14/1000)*INPUTS!$C$12*$G14)+INPUTS!$C$13+INPUTS!$C$14)/60) | K14: =IF($C14="","",J14*INPUTS!$C$8) | L14: =IF($C14="","",MAX(K14/(1-INPUTS!$C$18),INPUTS!$C$20)) | M14: =IF($C14="","",L14*INPUTS!$C$21/12) | N14: =IF($C14="","",L14*INPUTS!$C$21) | O14: =IF($C14="","",(L14-K14)/L14) | P14: =IF(OR($C14="",I14=0),"",L14/I14) | Q14: =IF($C14="","",(L14-K14)*INPUTS!$C$21*INPUTS!$C$24) | R14: =IF($C14="","",TRIM(IF(I14>INPUTS!$C$27,"Large; ","")&IF(AND($C14>0,($D14/$C14)>INPUTS!$C$28),"Bed-heavy; ","")&IF(M14>INPUTS!$C$29,"High-value; ","")&IF($H14="Low","Low-confidence; ","")&IF(AND(I14>=1,IFERROR(L14/I14,0)<INPUTS!$C$30),"Below-market; ","")&IF(AND(I14>=1,IFERROR(L14/I14,0)>INPUTS!$C$31),"Above-market; ",""))) | S14: =IF($C14="","",IF(R14="","NO","YES"))
I15: =IF($C15="","",$C15/43560) | J15: =IF($C15="","",((I15*INPUTS!$C$11*$G15)+(($D15/1000)*INPUTS!$C$12*$G15)+INPUTS!$C$13+INPUTS!$C$14)/60) | K15: =IF($C15="","",J15*INPUTS!$C$8) | L15: =IF($C15="","",MAX(K15/(1-INPUTS!$C$18),INPUTS!$C$20)) | M15: =IF($C15="","",L15*INPUTS!$C$21/12) | N15: =IF($C15="","",L15*INPUTS!$C$21) | O15: =IF($C15="","",(L15-K15)/L15) | P15: =IF(OR($C15="",I15=0),"",L15/I15) | Q15: =IF($C15="","",(L15-K15)*INPUTS!$C$21*INPUTS!$C$24) | R15: =IF($C15="","",TRIM(IF(I15>INPUTS!$C$27,"Large; ","")&IF(AND($C15>0,($D15/$C15)>INPUTS!$C$28),"Bed-heavy; ","")&IF(M15>INPUTS!$C$29,"High-value; ","")&IF($H15="Low","Low-confidence; ","")&IF(AND(I15>=1,IFERROR(L15/I15,0)<INPUTS!$C$30),"Below-market; ","")&IF(AND(I15>=1,IFERROR(L15/I15,0)>INPUTS!$C$31),"Above-market; ",""))) | S15: =IF($C15="","",IF(R15="","NO","YES"))
I16: =IF($C16="","",$C16/43560) | J16: =IF($C16="","",((I16*INPUTS!$C$11*$G16)+(($D16/1000)*INPUTS!$C$12*$G16)+INPUTS!$C$13+INPUTS!$C$14)/60) | K16: =IF($C16="","",J16*INPUTS!$C$8) | L16: =IF($C16="","",MAX(K16/(1-INPUTS!$C$18),INPUTS!$C$20)) | M16: =IF($C16="","",L16*INPUTS!$C$21/12) | N16: =IF($C16="","",L16*INPUTS!$C$21) | O16: =IF($C16="","",(L16-K16)/L16) | P16: =IF(OR($C16="",I16=0),"",L16/I16) | Q16: =IF($C16="","",(L16-K16)*INPUTS!$C$21*INPUTS!$C$24) | R16: =IF($C16="","",TRIM(IF(I16>INPUTS!$C$27,"Large; ","")&IF(AND($C16>0,($D16/$C16)>INPUTS!$C$28),"Bed-heavy; ","")&IF(M16>INPUTS!$C$29,"High-value; ","")&IF($H16="Low","Low-confidence; ","")&IF(AND(I16>=1,IFERROR(L16/I16,0)<INPUTS!$C$30),"Below-market; ","")&IF(AND(I16>=1,IFERROR(L16/I16,0)>INPUTS!$C$31),"Above-market; ",""))) | S16: =IF($C16="","",IF(R16="","NO","YES"))
I17: =IF($C17="","",$C17/43560) | J17: =IF($C17="","",((I17*INPUTS!$C$11*$G17)+(($D17/1000)*INPUTS!$C$12*$G17)+INPUTS!$C$13+INPUTS!$C$14)/60) | K17: =IF($C17="","",J17*INPUTS!$C$8) | L17: =IF($C17="","",MAX(K17/(1-INPUTS!$C$18),INPUTS!$C$20)) | M17: =IF($C17="","",L17*INPUTS!$C$21/12) | N17: =IF($C17="","",L17*INPUTS!$C$21) | O17: =IF($C17="","",(L17-K17)/L17) | P17: =IF(OR($C17="",I17=0),"",L17/I17) | Q17: =IF($C17="","",(L17-K17)*INPUTS!$C$21*INPUTS!$C$24) | R17: =IF($C17="","",TRIM(IF(I17>INPUTS!$C$27,"Large; ","")&IF(AND($C17>0,($D17/$C17)>INPUTS!$C$28),"Bed-heavy; ","")&IF(M17>INPUTS!$C$29,"High-value; ","")&IF($H17="Low","Low-confidence; ","")&IF(AND(I17>=1,IFERROR(L17/I17,0)<INPUTS!$C$30),"Below-market; ","")&IF(AND(I17>=1,IFERROR(L17/I17,0)>INPUTS!$C$31),"Above-market; ",""))) | S17: =IF($C17="","",IF(R17="","NO","YES"))
I18: =IF($C18="","",$C18/43560) | J18: =IF($C18="","",((I18*INPUTS!$C$11*$G18)+(($D18/1000)*INPUTS!$C$12*$G18)+INPUTS!$C$13+INPUTS!$C$14)/60) | K18: =IF($C18="","",J18*INPUTS!$C$8) | L18: =IF($C18="","",MAX(K18/(1-INPUTS!$C$18),INPUTS!$C$20)) | M18: =IF($C18="","",L18*INPUTS!$C$21/12) | N18: =IF($C18="","",L18*INPUTS!$C$21) | O18: =IF($C18="","",(L18-K18)/L18) | P18: =IF(OR($C18="",I18=0),"",L18/I18) | Q18: =IF($C18="","",(L18-K18)*INPUTS!$C$21*INPUTS!$C$24) | R18: =IF($C18="","",TRIM(IF(I18>INPUTS!$C$27,"Large; ","")&IF(AND($C18>0,($D18/$C18)>INPUTS!$C$28),"Bed-heavy; ","")&IF(M18>INPUTS!$C$29,"High-value; ","")&IF($H18="Low","Low-confidence; ","")&IF(AND(I18>=1,IFERROR(L18/I18,0)<INPUTS!$C$30),"Below-market; ","")&IF(AND(I18>=1,IFERROR(L18/I18,0)>INPUTS!$C$31),"Above-market; ",""))) | S18: =IF($C18="","",IF(R18="","NO","YES"))
... I28: =IF($C28="","",$C28/43560) | J28: =IF($C28="","",((I28*INPUTS!$C$11*$G28)+(($D28/1000)*INPUTS!$C$12*$G28)+INPUTS!$C$13+INPUTS!$C$14)/60) | K28: =IF($C28="","",J28*INPUTS!$C$8) | L28: =IF($C28="","",MAX(K28/(1-INPUTS!$C$18),INPUTS!$C$20)) | M28: =IF($C28="","",L28*INPUTS!$C$21/12) | N28: =IF($C28="","",L28*INPUTS!$C$21) | O28: =IF($C28="","",(L28-K28)/L28) | P28: =IF(OR($C28="",I28=0),"",L28/I28) | Q28: =IF($C28="","",(L28-K28)*INPUTS!$C$21*INPUTS!$C$24) | R28: =IF($C28="","",TRIM(IF(I28>INPUTS!$C$27,"Large; ","")&IF(AND($C28>0,($D28/$C28)>INPUTS!$C$28),"Bed-heavy; ","")&IF(M28>INPUTS!$C$29,"High-value; ","")&IF($H28="Low","Low-confidence; ","")&IF(AND(I28>=1,IFERROR(L28/I28,0)<INPUTS!$C$30),"Below-market; ","")&IF(AND(I28>=1,IFERROR(L28/I28,0)>INPUTS!$C$31),"Above-market; ",""))) | S28: =IF($C28="","",IF(R28="","NO","YES"))

Sheet MARKET REFERENCE
B2: MARKET REFERENCE — Texas / Houston benchmarks behind the defaults
B4: Benchmark | C4: Value | D4: Source
B5: Commercial mowing, lots < 5 acres | C5: $50-150 / acre / week | D5: HomeGuide / GreenPal, 2026, Houston TX
B6: Commercial mowing, lots 5+ acres | C6: $25-60 / acre / week | D6: HomeGuide commercial lawn care, Feb 2026
B7: Full-service commercial maintenance | C7: $800-1,600 / acre / month | D7: GreenPal Houston lawn care, May 2026
B8: Commercial labor (billed) per worker | C8: $40-80 / hour | D8: HomeGuide commercial, Feb 2026
B9: Suburban route advantage | C9: Lower cost vs Inner Loop (30-40% loop premium) | D9: GreenPal Houston, 2026 (Cypress/Woodlands stack stops)
B10: Edging | C10: $0.50-1.00 / linear ft | D10: HomeGuide commercial, 2026
B11: Shrub / bush trimming (periodic) | C11: $5-20 per bush | D11: HomeGuide commercial, 2026
B12: Houston growing season | C12: Weekly ~Mar-Oct, biweekly shoulder | D12: GreenPal / warm-season turf (Bermuda, St. Aug)
B13: Takeoff tool (SiteRecon) | C13: $39/mo Scout up to 10 ac; $250-500/mo flat tiers; open API | D13: SiteRecon / Capterra, Mar 2026
B14: Cost per estimate with auto-measurement | C14: ~$5-10 vs $150-300 manual | D14: SiteRecon, May 2026
B16: These are educated defaults. Replace with your friend's actual numbers as you learn them from real jobs.
